Workbook

Sheet Стоимость оценки
B2: Коэффициенты | E2: Итоговая стоимость оценки
B4: Элемент | C4: Дополнения | E4: Элемент | F4: Значение
B5: Сколько требуется экземпляров отчета / заключения? | C5: 2 | E5: Направление оценки | F5: Недвижимость
B6: Требуется ли выезд на объект оценки? | E6: Объект оценки | F6: Отдельное здание коммерческое / производственное / складское
B7: Срочная оценка | E7: Основной ценообразующий параметр | F7: =IF(F6="Земельный участок некоммерческий","соток",IF(F5="Недвижимость","кв.м",IF(F5="Бизнес","Выручка, млн руб.",IF(OR(F5="Движимое имущество",F5="Услуги",F5="Другое"),"ед.","")))) -> кв.м
B8: Оценка на дату предыдущих лет | C8: TRUE | E8: Значение ценообразующего параметра | F8: 506
B9: Оценка арендной ставки | C9: TRUE | E9: Формат документа | F9: Заключение эксперта (судебная экспертиза)
B10: Оспаривание кадастровой стоимости | E10: Кто будет выезжать на объект оценки | F10: =IF(F9="Заключение эксперта (судебная экспертиза)",IF(C8=TRUE,"Никто","Оценщик"),IF(C6=TRUE,"Водитель","Никто")) -> Никто
B11: Оценка упущенной выгоды (без изъятия) | E11: Стоимость бензина | F11: =IF(OR(F10="Никто",F10=""),0,IF(F10="Оценщик",'Калькулятор выезда'!F10,'Калькулятор выезда'!C10))/0.9 -> 0
B12: Оценка при изъятии | E12: Стоимость выезда | F12: =IF(OR(F10="Никто",F10=""),0,IF(F10="Оценщик",'Калькулятор выезда'!F11,'Калькулятор выезда'!C11))* IF(C7=TRUE,VLOOKUP(B7,Дополнительное!$A:$C,2,0),1)* IF(C8=TRUE,VLOOKUP(B8,Дополнительное!$A:$C,2,0),1)* IF(C9=TRUE,VLOOKUP(B9,Дополнительное!$A:$C,2,0),1)* IF(C10=TRUE,VLOOKUP(B10,Дополнительное!$A:$C,2,0),1)* IF(C11=TRUE,VLOOKUP(B11,Дополнительное!$A:$C,2,0),1)* IF(C12=TRUE,VLOOKUP(B12,Дополнительное!$A:$C,2,0),1)* IF(C13=TRUE,VLOOKUP(B13,Дополнительное!$A:$C,2,0),1)* IF(F9="Заключение эксперта (судебная экспертиза)",2,1) -> 0
B13: Оценка при приватизации | E13: Наряд Оценщика (без учета выезда) | F13: =IF(F7="ед.",VLOOKUP(F6,'Расчет наряда'!$C$2:$E$14,3,0)*F8,VLOOKUP(F6,Списки!$M$5:$N$11,2,0))* IF(C7=TRUE,VLOOKUP(B7,Дополнительное!$A:$C,2,0),1)* IF(C8=TRUE,VLOOKUP(B8,Дополнительное!$A:$C,2,0),1)* IF(C9=TRUE,VLOOKUP(B9,Дополнительное!$A:$C,2,0),1)* IF(C10=TRUE,VLOOKUP(B10,Дополнительное!$A:$C,2,0),1)* IF(C11=TRUE,VLOOKUP(B11,Дополнительное!$A:$C,2,0),1)* IF(C12=TRUE,VLOOKUP(B12,Дополнительное!$A:$C,2,0),1)* IF(C13=TRUE,VLOOKUP(B13,Дополнительное!$A:$C,2,0),1)* IF(C14=TRUE,VLOOKUP(B14,Дополнительное!$A:$C,2,0),1)* IF(F9="Заключение эксперта (судебная экспертиза)",2,1)* IF(F9="Экспертное заключение",0.9,1) -> 54144.419
B14: Расчет упущенной выгоды | C14: TRUE | E14: Заказчик (Физическое или Юридическое лицо) | F14: Юридическое лицо
E15: Ориентировочная стоимость оценки | F15: =IF( AND(F10="Водитель",F9="Заключение эксперта (судебная экспертиза)"), "Водитель не может выехать на объект экспертизы по судебной экспертизе", ROUND( (F11+(F12+F13)/0.87*4),-2)+IF(C5>=2,C5*VLOOKUP(B5,Дополнительное!$A$1:$B$12,2,0),0)) -> 258900
B16: Дополнения (вне договора)
B17: Элемент | C17: Значение
B18: Выезд эксперта в суд | C18: 45000

Sheet Калькулятор выезда
B2: Расчет стоимости выезда Водителя | E2: Расчет стоимости выезда Оценщика
B4: Показатель | C4: Значение | E4: Показатель | F4: Значение
B5: Стоимость бензина А95 за 1 литр, руб. | C5: 67.5 | E5: Стоимость бензина А95 за 1 литр, руб. | F5: =C5 -> 67.5
B6: Средний расход 1 литра, км | C6: 10 | E6: Средний расход 1 литра, км | F6: =C6 -> 10
B7: Расстояние от офиса до объекта оценки, км | C7: 50 | E7: Расстояние от офиса до объекта оценки, км | F7: =C7 -> 50
B8: Ориентировочное время на объекте оценки, ч | C8: 2 | E8: Ориентировочное время на объекте оценки, ч | F8: =C8 -> 2
B9: Стоимость проезда по платной дороге, руб. | C9: 600 | E9: Стоимость проезда по платной дороге, руб. | F9: =C9 -> 600
B10: Стоимость бензина и проезда без налогов и сборов | C10: =C7/C6*C5+C9 -> 937.5 | E10: Стоимость бензина без налогов и сборов | F10: =F7/F6*F5+F9 -> 937.5
B11: Стоимость водителя без налогов и сборов | C11: =C8/8*3000 -> 750 | E11: Стоимость оценщика без налогов и сборов | F11: =F8/8*6000 -> 1500
B12: Стоимость бензина и водителя с налогами и сборами | C12: =ROUND((C11/0.87*4+C10/0.9),-2) -> 4500 | E12: Стоимость бензина и оценщика с налогами и сборами | F12: =ROUND((F11/0.87*4+F10/0.9),-2) -> 7900
B16: Источник стоимости бензина А95 | C16: https://www.petrolplus.ru/fuelindex/gorod-moskva/ai95/
B17: Источник для построения маршрута | C17: https://yandex.ru/maps/213/moscow/?ll=37.600672%2C55.735591&mode=routes&rtext=55.734385%2C37.591342&rtt=pd&ruri=ymapsbm1%3A%2F%2Fgeo%3Fdata%3DCgg1NjY5ODAyORJH0KDQvtGB0YHQuNGPLCDQnNC-0YHQutCy0LAsINGD0LvQuNGG0LAg0KLQuNC80YPRgNCwINCk0YDRg9C90LfQtSwgMTbRgTMiC

Sheet Стоимости оценок и нарядов
A3: Названия строк | B3: Мин. стоимость услуги, руб. | C3: Мин. срок работы, дн. | D3: Мин. Наряд оценщика
A4: Авто импортное | B4: 5150 | C4: 1.5 | D4: =ROUND($B4/4/1.13/1.05,500) -> 1085.1243
A5: Авто отечественное | B5: 4233.3333 | C5: 1.5 | D5: =ROUND($B5/4/1.13/1.05,500) -> 891.97921
A6: Авто элитное | B6: 5750 | C6: 2 | D6: =ROUND($B6/4/1.13/1.05,500) -> 1211.5466
A7: Акции (котируемые) | B7: 8875 | C7: 2.5 | D7: =ROUND($B7/4/1.13/1.05,500) -> 1869.9958
A8: Акции (некотируемые) | B8: 10666.667 | C8: 3 | D8: =ROUND($B8/4/1.13/1.05,500) -> 2247.5067
A9: Анализ финансово-хозяйственной деятельности предприятия | B9: 6000 | C9: 3 | D9: =ROUND($B9/4/1.13/1.05,500) -> 1264.2225
A10: Встроенные помещения коммерческие от 5000 м2 | B10: 58250 | C10: 5 | D10: =ROUND($B10/4/1.13/1.05,500) -> 12273.493
A11: Встроенные помещения коммерческие 1000-5000 м2 | B11: 46250 | C11: 4.5 | D11: =ROUND($B11/4/1.13/1.05,500) -> 9745.0485
A12: Встроенные помещения коммерческие 300-500 м2 | B12: 25000 | C12: 6.3333333 | D12: =ROUND($B12/4/1.13/1.05,500) -> 5267.5938
A13: Встроенные помещения коммерческие 500-1000 м2 | B13: 36250 | C13: 4.5 | D13: =ROUND($B13/4/1.13/1.05,500) -> 7638.011
A14: Встроенные помещения коммерческие до 300 м2 | B14: 16166.667 | C14: 4.25 | D14: =ROUND($B14/4/1.13/1.05,500) -> 3406.3773
A15: Деловая репутация | B15: 40000 | C15: 2.5 | D15: =ROUND($B15/4/1.13/1.05,500) -> 8428.15
A16: Долговые обязательства | B16: 20000 | D16: =ROUND($B16/4/1.13/1.05,500) -> 4214.075
A17: Доли ООО | B17: 26666.667 | C17: 5 | D17: =ROUND($B17/4/1.13/1.05,500) -> 5618.7667
A18: Доп. постройки (1 ед.) | B18: 3000 | D18: =ROUND($B18/4/1.13/1.05,500) -> 632.11125
A19: Другие НМА | B19: 26666.667 | C19: 2.5 | D19: =ROUND($B19/4/1.13/1.05,500) -> 5618.7667
A20: Жилой дом до 100 м2 с участком | B20: 11000 | C20: 4.3333333 | D20: =ROUND($B20/4/1.13/1.05,500) -> 2317.7413
A21: Жилой дом до 300 м2 с участком | B21: 13750 | C21: 4.3333333 | D21: =ROUND($B21/4/1.13/1.05,500) -> 2897.1766
A22: Жилой дом до 500 м2 с участком | B22: 43333.333 | C22: 3 | D22: =ROUND($B22/4/1.13/1.05,500) -> 9130.4959
A23: Земельный участок некоммерческий 100-500 соток | B23: 45000 | C23: 2 | D23: =ROUND($B23/4/1.13/1.05,500) -> 9481.6688
A24: Земельный участок некоммерческий 10-50 соток | B24: 16500 | C24: 2 | D24: =ROUND($B24/4/1.13/1.05,500) -> 3476.6119
A25: Земельный участок некоммерческий 500-2000 соток | B25: 60000 | C25: 2 | D25: =ROUND($B25/4/1.13/1.05,500) -> 12642.225
A26: Земельный участок некоммерческий 50-100 соток | B26: 26500 | C26: 2 | D26: =ROUND($B26/4/1.13/1.05,500) -> 5583.6494
A27: Земельный участок некоммерческий более 10 соток | B27: 14500 | C27: 6 | D27: =ROUND($B27/4/1.13/1.05,500) -> 3055.2044
A28: Земельный участок некоммерческий до 10 соток | B28: 11125 | C28: 5 | D28: =ROUND($B28/4/1.13/1.05,500) -> 2344.0792
A29: Земельный участок некоммерческий от 10 000 соток | B29: 85000 | C29: 2 | D29: =ROUND($B29/4/1.13/1.05,500) -> 17909.819
A30: Земельный участок с/х назначения до 10 га | B30: 24500 | C30: 6 | D30: =ROUND($B30/4/1.13/1.05,500) -> 5162.2419
... A48: Отчет об оценке активов для целей МСФО | B48: 22500 | C48: 5 | D48: =ROUND($B48/4/1.13/1.05,500) -> 4740.8344
A49: Офисное оборудование | B49: 500 | D49: =ROUND($B49/4/1.13/1.05,500) -> 105.35188
A50: Оценка арендной ставки | B50: 19000 | C50: 2 | D50: =ROUND($B50/4/1.13/1.05,500) -> 4003.3713
A51: Оценка имущества при приватизации | B51: 20000 | D51: =ROUND($B51/4/1.13/1.05,500) -> 4214.075
A52: Оценка недвижимости для оспаривания кадастровой стоимости | B52: 26333.333 | D52: =ROUND($B52/4/1.13/1.05,500) -> 5548.5321
A53: Оценка упущенной выгоды | B53: 25000 | D53: =ROUND($B53/4/1.13/1.05,500) -> 5267.5938
A54: Патент | B54: 28333.333 | C54: 2.5 | D54: =ROUND($B54/4/1.13/1.05,500) -> 5969.9396
A55: Регистрация прав собственности + отчет об оценке | B55: 12000 | D55: =ROUND($B55/4/1.13/1.05,500) -> 2528.445
A56: Серийное техническое оборудование, ед. | B56: 2214.2857 | C56: 3.6666667 | D56: =ROUND($B56/4/1.13/1.05,500) -> 466.5583
A57: Средний бизнес | B57: 70833.333 | C57: 9.5 | D57: =ROUND($B57/4/1.13/1.05,500) -> 14924.849
A58: Строительная техника | B58: 11500 | C58: 3.6666667 | D58: =ROUND($B58/4/1.13/1.05,500) -> 2423.0931
A59: Судебная экспертиза арендной ставки | B59: 20000 | C59: 3 | D59: =ROUND($B59/4/1.13/1.05,500) -> 4214.075
...

Sheet Информация по стоимостям
A1: Объект оценки | B1: Стоимость | C1: Комментарий к стоимости | D1: Срок работы | E1: Комментарий к сроку работы | F1: Ссылка | G1: Общий комментарий
A2: Квартира для опеки | B2: 2200 | F2: https://www.grand-real.ru/evaluation/otsenka-nedvizhimosti/
A3: Квартира, комната, доля в Москве, МО | B3: 3500 | F3: https://www.grand-real.ru/evaluation/otsenka-nedvizhimosti/
A4: Элитная квартира (от 90 м2) | B4: 6000 | F4: https://www.grand-real.ru/evaluation/otsenka-nedvizhimosti/
A5: Регистрация прав собственности + отчет об оценке | B5: 12000 | F5: https://www.grand-real.ru/evaluation/otsenka-nedvizhimosti/
A6: Земельный участок некоммерческий до 10 соток | B6: 3500 | C6: от | F6: https://www.grand-real.ru/evaluation/otsenka-nedvizhimosti/
A7: Земельный участок некоммерческий более 10 соток | B7: 5000 | C7: от | F7: https://www.grand-real.ru/evaluation/otsenka-nedvizhimosti/
A8: Жилой дом до 100 м2 с участком | B8: 5000 | C8: от | F8: https://www.grand-real.ru/evaluation/otsenka-nedvizhimosti/
A9: Жилой дом до 300 м2 с участком | B9: 7000 | C9: от | F9: https://www.grand-real.ru/evaluation/otsenka-nedvizhimosti/
A10: Жилой дом до 500 м2 с участком | B10: 85000 | C10: от | F10: https://www.grand-real.ru/evaluation/otsenka-nedvizhimosti/
A11: Элит. Жилой дом более 500 м2 с участком | B11: 15000 | C11: от | F11: https://www.grand-real.ru/evaluation/otsenka-nedvizhimosti/
A12: Доп. постройки (1 ед.) | B12: 3000 | F12: https://www.grand-real.ru/evaluation/otsenka-nedvizhimosti/
A13: Земельный участок с/х назначения до 10 га | B13: 15000 | C13: от | F13: https://www.grand-real.ru/evaluation/otsenka-nedvizhimosti/
A14: Земельный участок с/х назначения свыше 10 га | B14: 18000 | C14: от | F14: https://www.grand-real.ru/evaluation/otsenka-nedvizhimosti/
A15: Оценка недвижимости для оспаривания кадастровой стоимости | B15: 30000 | F15: https://www.grand-real.ru/evaluation/otsenka-nedvizhimosti/
A16: Участки коммерческого назначения до 1 га / 1 ед. | B16: 10000 | F16: https://www.grand-real.ru/evaluation/otsenka-nedvizhimosti/
A17: Участки коммерческого более 1 га / 1 ед. | B17: 15000 | C17: от | F17: https://www.grand-real.ru/evaluation/otsenka-nedvizhimosti/
A18: Встроенные помещения коммерческие до 300 м2 | B18: 8000 | F18: https://www.grand-real.ru/evaluation/otsenka-nedvizhimosti/
A19: Встроенные помещения коммерческие 300-500 м2 | B19: 12000 | F19: https://www.grand-real.ru/evaluation/otsenka-nedvizhimosti/
A20: Встроенные помещения коммерческие 500-1000 м2 | B20: 25000 | F20: https://www.grand-real.ru/evaluation/otsenka-nedvizhimosti/
A21: Встроенные помещения коммерческие 1000-5000 м2 | B21: 30000 | F21: https://www.grand-real.ru/evaluation/otsenka-nedvizhimosti/
A22: Встроенные помещения коммерческие от 5000 м2 | B22: 35000 | C22: от | F22: https://www.grand-real.ru/evaluation/otsenka-nedvizhimosti/
A23: Отдельное здание коммерческое до 500 м2 | B23: 15000 | F23: https://www.grand-real.ru/evaluation/otsenka-nedvizhimosti/
A24: Отдельное здание коммерческое 500-1000 м2 | B24: 20000 | F24: https://www.grand-real.ru/evaluation/otsenka-nedvizhimosti/
A25: Отдельное здание коммерческое 1000-5000 м2 | B25: 25000 | F25: https://www.grand-real.ru/evaluation/otsenka-nedvizhimosti/
A26: Отдельное здание от 5000 м2 | B26: 30000 | C26: от | F26: https://www.grand-real.ru/evaluation/otsenka-nedvizhimosti/
A27: Машино-место, гараж в Москве, МО | B27: 3000 | F27: https://www.grand-real.ru/evaluation/otsenka-nedvizhimosti/
A28: Оценка арендной ставки | B28: 10000 | C28: от | F28: https://www.grand-real.ru/evaluation/otsenka-nedvizhimosti/
A29: Авто отечественное | B29: 1500 | F29: https://www.grand-real.ru/evaluation/otsenka-nedvizhimosti/
A30: Авто импортное | B30: 2000 | F30: https://www.grand-real.ru/evaluation/otsenka-nedvizhimosti/
A31: Авто элитное | B31: 5000 | F31: https://www.grand-real.ru/evaluation/otsenka-nedvizhimosti/
A32: Оружие | B32: 2000 | C32: от | F32: https://www.grand-real.ru/evaluation/otsenka-nedvizhimosti/
A33: Офисное оборудование | B33: 500 | C33: от | F33: https://www.grand-real.ru/evaluation/otsenka-nedvizhimosti/
A34: Серийное техническое оборудование, ед. | B34: 1500 | F34: https://www.grand-real.ru/evaluation/otsenka-nedvizhimosti/ | G34: Не менее 17 000
A35: Строительная техника | B35: 5000 | F35: https://www.grand-real.ru/evaluation/otsenka-nedvizhimosti/
A36: Морские, речные, воздушные суда и ж/д транспорт | B36: 15000 | F36: https://www.grand-real.ru/evaluation/otsenka-nedvizhimosti/
A37: Технологические линии (заводы) | B37: 20000 | F37: https://www.grand-real.ru/evaluation/otsenka-nedvizhimosti/
A38: Акции (котируемые) | B38: 3500 | F38: https://www.grand-real.ru/evaluation/otsenka-nedvizhimosti/
A39: Акции (некотируемые) | B39: 5000 | F39: https://www.grand-real.ru/evaluation/otsenka-nedvizhimosti/
A40: Доли ООО | B40: 10000 | F40: https://www.grand-real.ru/evaluation/otsenka-nedvizhimosti/
...

Sheet Дополнительное
A1: Услуга | B1: Стоимость | C1: Примечание
A2: Сколько требуется экземпляров отчета / заключения? | B2: 5000
A3: Срочная оценка | B3: 1.5 | C3: Коэффициент
A4: Оценка на дату предыдущих лет | B4: 1.3 | C4: Коэффициент
A5: Судебная оценка | B5: 2 | C5: Коэффициент
A6: Оценка арендной ставки | B6: 1.1 | C6: Коэффициент
A7: Оспаривание кадастровой стоимости | B7: 1.3 | C7: Коэффициент
A8: Оценка упущенной выгоды (без изъятия) | B8: 1.2 | C8: Коэффициент
A9: Оценка при приватизации | B9: 1.3 | C9: Коэффициент
A10: Оценка при изъятии | B10: 1.5 | C10: Коэффициент
A11: Расчет упущенной выгоды | B11: 1.3 | C11: Коэффициент
A12: Нужно приблизиться к какому-то значению | B12: 1.3 | C12: Коэффициент

Sheet Расчет наряда
C2: Объект оценки | D2: Направление оценки | E2: Наряд Оценщика
C3: Акции (котируемые) | D3: Бизнес | E3: 1800
C4: Автомобиль (импортный) | D4: Движимое имущество | E4: 1500
C5: Автомобиль (отечественный) | D5: Движимое имущество | E5: 1500
C6: Автомобиль (элитный) | D6: Движимое имущество | E6: 2000 | H6: Формула для оценки наряда по встроенным помещениям коммерческим / производственным / складским в кв.м - МАКС(7000;12000*LN(кв.м)-50000)
C7: Анализ финансово-хозяйственной деятельности компании | D7: Экспертиза | E7: 1200 | H7: Формула для оценки наряда по жилому дому с ЗУ в кв.м - МАКС(3000;1200*LN(кв.м)-1500)
C8: Квартира (до 150 кв.м) | D8: Недвижимость | E8: 1500 | H8: Формула для оценки наряда по оценки бизнеса в зависимости от выручки компании в млн руб. - МАКС(10000;17000*LN(млн руб.)-80000)
C9: Квартира (более 150 кв.м) | D9: Недвижимость | E9: 2000 | H9: Формула для оценки наряда по ЗУ некоммерческим в сотках- МАКС(2000*LN(соток)-4000;2000)
C10: Машино-место, гараж, бокс в МСК и МО | D10: Недвижимость | E10: 1100 | H10: Формула для оценки наряда по отдельному коммерческому / производственному / складскому зданию в кв.м - МАКС(2500*LN(кв.м)-7000;5000)
C11: Оборудование распространенное (>50 всех ед.), за ед. | D11: Движимое имущество | E11: 200 | H11: Формула для оценки земельного участка с/х в кв.м - МАКС(7000*LN(кв.м)-70600;2000)
C12: Станок | D12: Движимое имущество | E12: 3000
C13: Оборудование нераспространенное, ед. | D13: Движимое имущество | E13: 1500
C14: Ущерб (залив, пожар) за помещение | D14: Экспертиза | E14: 4000
C15: Помещения, встроенные коммерческие | D15: Недвижимость
C16: Жилой дом с земельным участком | D16: Недвижимость
C17: Доля в уставном капитале | D17: Бизнес
C18: Земельный участок некоммерческий | D18: Недвижимость
C19: Земельный участок сельскохозяйственный | D19: Недвижимость
C20: Отдельное здание коммерческое / производственное / складское | D20: Недвижимость
C21: Другое | D21: Другое
C22: Услуга | D22: Услуга
B26: Названия строк | C26: Мин. стоимость услуги, руб. | D26: Мин. срок работы, дн. | E26: Мин. Наряд оценщика
B27: Другие НМА | C27: 26666.667 | D27: 2.5 | E27: 5618.7667
B28: Интеллектуальная собственность | C28: 33333.333 | D28: 5 | E28: 7023.4584
B29: Лицензия | C29: 30000 | D29: 2.5 | E29: 6321.1125
B30: Морские, речные, воздушные суда и ж/д транспорт | C30: 32500 | D30: 4.3333333 | E30: 6847.8719
B31: Ноу-хау | C31: 33333.333 | D31: 2.5 | E31: 7023.4584
B32: Отчет об оценке активов для целей МСФО | C32: 22500 | D32: 5 | E32: 4740.8344
B33: Патент | C33: 28333.333 | D33: 2.5 | E33: 5969.9396
B34: Регистрация прав собственности + отчет об оценке | C34: 12000 | E34: 2528.445
B35: Судебная экспертиза воздушного судна | C35: 60000 | D35: 7 | E35: 12642.225
B36: Судебная экспертиза дебиторской задолженности | C36: 40000 | D36: 5 | E36: 8428.15
B37: Судебная экспертиза имущественного комплекса | C37: 100000 | D37: 7 | E37: 21070.375
B38: Судебная экспертиза интернет-сайта | C38: 60000 | D38: 7 | E38: 12642.225
B39: Судебная экспертиза морского судна | C39: 60000 | D39: 7 | E39: 12642.225
B40: Судебная экспертиза нежилых помещений | C40: 30000 | D40: 7 | E40: 6321.1125
B41: Судебная экспертиза нематериальных активов | C41: 80000 | D41: 5 | E41: 16856.3
B42: Судебная экспертиза рыночной вагона/локомотива | C42: 10000 | D42: 7 | E42: 2107.0375
B43: Технологические линии (заводы) | C43: 32500 | D43: 5 | E43: 6847.8719
B44: Товарный знак | C44: 30000 | D44: 2.5 | E44: 6321.1125

Sheet Списки
A1: Кто будет выезжать на объект оценки | C1: Заказчик (физ. лицо или юр. лицо) | E1: Дополнение | G1: Формат документа | I1: Направление оценки | K1: Объект оценки | M1: Формула основного ценообразующего фактора
A2: Водитель | C2: Физическое лицо | E2: TRUE | G2: Отчет об оценке | I2: Недвижимость | K2: Акции (котируемые) | M2: ЕСЛИ(G5="Недвижимость";"кв.м";ЕСЛИ(G5="Бизнес";"млн руб.";ЕСЛИ(G5="Движимое имущество";"ед.";"")))
A3: Оценщик | C3: Юридическое лицо | E3: FALSE | G3: Экспертное заключение | I3: Движимое имущество | K3: Автомобиль (импортный)
A4: Никто | G4: Заключение эксперта (судебная экспертиза) | I4: Бизнес | K4: Автомобиль (отечественный)
I5: Услуга | K5: Автомобиль (элитный) | M5: Доп. расчеты: | N5: Значение
I6: Экспертиза | K6: Анализ финансово-хозяйственной деятельности компании | M6: Помещения, встроенные коммерческие | N6: =MAX(2500*LN('Стоимость оценки'!F$8)-7000,5000)*1.5 -> 12849.513
I7: Другое | K7: Квартира (до 150 кв.м) | M7: =K15 -> Жилой дом с земельным участком | N7: =MAX(6500,1200*LN('Стоимость оценки'!F8)-1500) -> 6500
K8: Квартира (более 150 кв.м) | M8: =K16 -> Доля в уставном капитале | N8: =MAX(12500,17000*LN('Стоимость оценки'!F8)-80000) -> 25851.123
K9: Машино-место, гараж, бокс в МСК и МО | M9: =K17 -> Земельный участок некоммерческий | N9: =MAX((2000*LN('Стоимость оценки'!F8)-4000)*2,2000) -> 16906.147
K10: Оборудование распространенное (>50 всех ед.), за ед. | M10: =K19 -> Отдельное здание коммерческое / производственное / складское | N10: =MAX(2500*LN('Стоимость оценки'!F8)-7000,5000)*1.7 -> 14562.781
K11: Станок | M11: =K18 -> Земельный участок сельскохозяйственный | N11: =MAX(7000*LN('Стоимость оценки'!F8)-70600,2000) -> 2000
K12: Оборудование нераспространенное, ед.
K13: Ущерб (залив, пожар) за помещение | M13: Формула для оценки наряда по встроенным помещениям коммерческим / производственным / складским в кв.м - МАКС(7000;12000*LN(кв.м)-50000)
K14: Помещения, встроенные коммерческие | M14: Формула для оценки наряда по жилому дому с ЗУ в кв.м - МАКС(3000;1200*LN(кв.м)-1500)
K15: Жилой дом с земельным участком | M15: Формула для оценки наряда по оценки бизнеса в зависимости от выручки компании в млн руб. - МАКС(10000;17000*LN(млн руб.)-80000)
K16: Доля в уставном капитале | M16: Формула для оценки наряда по ЗУ некоммерческим в сотках- МАКС(2000*LN(соток)-4000;2000)
K17: Земельный участок некоммерческий | M17: Формула для оценки наряда по отдельному коммерческому / производственному / складскому зданию в кв.м - МАКС(2500*LN(кв.м)-7000;5000)
K18: Земельный участок сельскохозяйственный | M18: Формула для оценки земельного участка с/х в кв.м - МАКС(7000*LN(кв.м)-70600;2000)
K19: Отдельное здание коммерческое / производственное / складское
K20: Другое
